<?xml version="1.0" encoding="UTF-8"?>
<!-- Generated by org.testng.reporters.JUnitXMLReporter -->
<testsuite hostname="DESKTOP-CTUFDT2" ignored="0" name="Default test" tests="3" failures="1" timestamp="27 Nov 2022 16:21:19 GMT" time="47.621" errors="0">
  <testcase name="SubmitOrder" time="17.125" classname="learningspace.tests.SubmitOrderTest"/>
  <testcase name="SubmitOrder" time="16.038" classname="learningspace.tests.SubmitOrderTest"/>
  <testcase name="VerifyOrder" time="0.001" classname="learningspace.tests.SubmitOrderTest">
    <failure type="org.testng.internal.reflect.MethodMatcherException" message="
Data provider mismatch
Method: VerifyOrder([Parameter{index=0, type=java.lang.String, declaredAnnotations=[]}, Parameter{index=1, type=java.lang.String, declaredAnnotations=[]}, Parameter{index=2, type=java.lang.String, declaredAnnotations=[]}])
Arguments: [(java.util.HashMap) {password=testA1@gmail.com, email=testA1@gmail.com, productName=ZARA COAT 3}]">
      <![CDATA[org.testng.internal.reflect.MethodMatcherException: 
Data provider mismatch
Method: VerifyOrder([Parameter{index=0, type=java.lang.String, declaredAnnotations=[]}, Parameter{index=1, type=java.lang.String, declaredAnnotations=[]}, Parameter{index=2, type=java.lang.String, declaredAnnotations=[]}])
Arguments: [(java.util.HashMap) {password=testA1@gmail.com, email=testA1@gmail.com, productName=ZARA COAT 3}]
at org.testng.internal.reflect.DataProviderMethodMatcher.getConformingArguments(DataProviderMethodMatcher.java:45)
at org.testng.internal.Parameters.injectParameters(Parameters.java:796)
at org.testng.internal.Invoker.invokeTestMethods(Invoker.java:983)
at org.testng.internal.TestMethodWorker.invokeTestMethods(TestMethodWorker.java:125)
at org.testng.internal.TestMethodWorker.run(TestMethodWorker.java:109)
at org.testng.TestRunner.privateRun(TestRunner.java:648)
at org.testng.TestRunner.run(TestRunner.java:505)
at org.testng.SuiteRunner.runTest(SuiteRunner.java:455)
at org.testng.SuiteRunner.runSequentially(SuiteRunner.java:450)
at org.testng.SuiteRunner.privateRun(SuiteRunner.java:415)
at org.testng.SuiteRunner.run(SuiteRunner.java:364)
at org.testng.SuiteRunnerWorker.runSuite(SuiteRunnerWorker.java:52)
at org.testng.SuiteRunnerWorker.run(SuiteRunnerWorker.java:84)
at org.testng.TestNG.runSuitesSequentially(TestNG.java:1208)
at org.testng.TestNG.runSuitesLocally(TestNG.java:1137)
at org.testng.TestNG.runSuites(TestNG.java:1049)
at org.testng.TestNG.run(TestNG.java:1017)
at org.testng.remote.AbstractRemoteTestNG.run(AbstractRemoteTestNG.java:132)
at org.testng.remote.RemoteTestNG.initAndRun(RemoteTestNG.java:230)
at org.testng.remote.RemoteTestNG.main(RemoteTestNG.java:76)
]]>
    </failure>
  </testcase> <!-- VerifyOrder -->
</testsuite> <!-- Default test -->
